Workbook

Sheet Calculator
A2: DealWiseRent.com | Rental Property Investment Calculator
A4: 📝 INSTRUCTIONS: Enter values in BLUE cells. GREEN cells auto-calculate. Do NOT edit green cells.
B6: 💰 COST ASSUMPTIONS | E6: 🏦 FINANCING | H6: 📈 REVENUE & GROWTH | K6: 🏘 UNIT DETAILS
B7: Purchase Price | C7: 75000 | E7: Downpayment % | F7: 0.25 | H7: Monthly Rent / Unit | I7: 1300 | K7: Number of Units | L7: 1
B8: Improvements / Rehab | C8: 10000 | E8: Interest Rate (Annual) | F8: 0.0568 | H8: Vacancy Rate | I8: 0.05 | K8: Square Footage | L8: 1800
B9: Closing Costs | C9: 8000 | E9: Loan Term (Years) | F9: 30 | H9: Annual Revenue Growth | I9: 0.02 | K9: Avg Tenant Stay | L9: 2
B10: Land Value (25%) | C10: =C7*0.25 -> 18750 | E10: Finance Amount | F10: =C7*(1-F7) -> 56250 | H10: Annual Expense Growth | I10: 0.02 | K10: PM Fee (% of Income) | L10: 0.08
B11: Building Value (75%) | C11: =C7*0.75 -> 56250 | E11: Downpayment Amount | F11: =C7*F7 -> 18750 | H11: Property Taxes (Annual) | I11: 2500 | K11: Insurance (Annual) | L11: 700
B12: Total Investment Cost | C12: =C7+C8+C9 -> 93000 | E12: Monthly Mortgage Pmt | F12: =IFERROR(ABS(PMT(F8/12,F9*12,F10)),0) -> 325.76267 | H12: Maintenance (Annual) | I12: 500 | K12: HOA Dues (Monthly) | L12: 0
E13: Total Cash Outlay | F13: =F11+C8+C9 -> 36750 | H13: Tenant Placement (Yr1) | I13: 650 | K13: Other Annual Expenses | L13: 0
B15: 🔵 Blue = User Input | E15: 🟢 Green = Auto-Calculated | H15: ⚠ Yellow = Needs Attention | K15: 📊 See Charts tab for visuals
B17: 📊 YEAR 1 RESULTS SUMMARY — Outsourced PM vs. Self-Managed
B18: METRIC | E18: OUTSOURCED PROP. MGMT | H18: SELF-MANAGED | K18: NOTES
B19: Gross Annual Rent | E19: =I7*12*L7 -> 15600 | H19: =I7*12*L7 -> 15600 | K19: Rent × 12 months × units
B20: Vacancy / Credit Loss (−) | E20: =-I7*12*L7*I8 -> -780 | H20: =-I7*12*L7*I8 -> -780 | K20: Vacancy rate × gross rent
B21: Effective Gross Income (EGI) | E21: =E19+E20 -> 14820 | H21: =H19+H20 -> 14820 | K21: Revenue after vacancy
B22: ─── Operating Expenses ───
B23: Property Taxes | E23: =-I11 -> -2500 | H23: =-I11 -> -2500 | K23: Annual
B24: Insurance | E24: =-L11 -> -700 | H24: =-L11 -> -700 | K24: Annual
B25: Maintenance & Repairs | E25: =-I12 -> -500 | H25: =-I12 -> -500 | K25: Annual
B26: PM Fee (outsourced / self) | E26: =-E21*L10 -> -1185.6 | H26: =0 -> 0 | K26: % of EGI outsourced; $0 self-managed
B27: HOA Dues | E27: =IF(L12>0,-L12*12,0) -> 0 | H27: =IF(L12>0,-L12*12,0) -> 0 | K27: Monthly×12
B28: Tenant Placement Fee (Yr1) | E28: =-I13 -> -650 | H28: =-I13 -> -650 | K28: First year only
B29: Other Annual Expenses | E29: =-L13 -> 0 | H29: =-L13 -> 0 | K29: Annual
B30: Total Operating Expenses | E30: =E23+E24+E25+E26+E27+E28+E29 -> -5535.6 | H30: =H23+H24+H25+H26+H27+H28+H29 -> -4350 | K30: Sum of all operating costs
B31: ─── Net Income & Cash Flow ───
B32: Net Operating Income (NOI) | E32: =E21+E30 -> 9284.4 | H32: =H21+H30 -> 10470 | K32: EGI + Total Expenses (expenses are negative)
B33: Annual Mortgage Payments | E33: =-F12*12 -> -3909.152 | H33: =-F12*12 -> -3909.152 | K33: Monthly payment × 12
B34: Annual Cash Flow | E34: =E32+E33 -> 5375.248 | H34: =H32+H33 -> 6560.848 | K34: NOI – Debt Service
B35: Monthly Cash Flow | E35: =E34/12 -> 447.93733 | H35: =H34/12 -> 546.73733 | K35: Annual CF ÷ 12
B36: ─── Returns & Ratios ───
B37: Cash ROI | E37: =IFERROR(E34/F13,0) -> 0.14626525 | H37: =IFERROR(H34/F13,0) -> 0.17852648 | K37: Annual CF ÷ Cash Outlay
B38: Total ROI (CF + Equity, Yr1) | E38: =IFERROR((E34-CUMPRINC(F8/12,F9*12,F10,1,12,0))/F13,0) -> 0.16621192 | H38: =IFERROR((H34-CUMPRINC(F8/12,F9*12,F10,1,12,0))/F13,0) -> 0.19847315 | K38: Includes principal paydown
B39: Cap Rate (NOI / Total Cost) | E39: =IFERROR(E32/C12,0) -> 0.099832258 | H39: =IFERROR(H32/C12,0) -> 0.11258065 | K39: Unlevered yield on cost
B40: Gross Rent Multiplier (GRM) | E40: =IFERROR(C7/E19,0) -> 4.8076923 | H40: =IFERROR(C7/H19,0) -> 4.8076923 | K40: Purchase Price ÷ Gross Rent
B41: Rent per Sq Ft / Year | E41: =IFERROR(I7*12/L8,0) -> 8.6666667 | H41: =IFERROR(I7*12/L8,0) -> 8.6666667 | K41: Monthly rent × 12 ÷ sq ft
B43: 📊 30-YEAR CASH FLOW & RETURNS PROJECTION (Outsourced Property Management)
B44: Year | C44: Gross Rent | D44: Eff. Gross Income | E44: Total Expenses | F44: NOI | G44: Annual Mortgage | H44: Annual Cash Flow | I44: Cash ROI % | J44: Equity Gained | K44: Cum. Equity | L44: Total ROI %
B45: 1 | C45: =$I$7*12*$L$7 -> 15600 | D45: =C45*(1-$I$8) -> 14820 | E45: =($I$11+$L$11+$I$12+IF($L$12>0,$L$12*12,0)+$I$13+$L$13)+D45*$L$10 -> 5535.6 | F45: =D45-E45 -> 9284.4 | G45: =$F$12*12 -> 3909.152 | H45: =F45-G45 -> 5375.248 | I45: =IFERROR(H45/$F$13,0) -> 0.14626525 | J45: =IFERROR(-CUMPRINC($F$8/12,$F$9*12,$F$10,(1-1)*12+1,1*12,0),0) -> 733.04028 | K45: =J45 -> 733.04028 | L45: =IFERROR((H45+J45)/$F$13,0) -> 0.16621192
B46: 2 | C46: =C45*(1+$I$9) -> 15912 | D46: =C46*(1-$I$8) -> 15116.4 | E46: =($I$11*(1+$I$10)^(2-1)+$L$11*(1+$I$10)^(2-1)+$I$12*(1+$I$10)^(2-1)+IF($L$12>0,$L$12*12*(1+$I$10)^(2-1),0)+$L$13*(1+$I$10)^(2-1))+D46*$L$10 -> 4983.312 | F46: =D46-E46 -> 10133.088 | G46: =$F$12*12 -> 3909.152 | H46: =F46-G46 -> 6223.936 | I46: =IFERROR(H46/$F$13,0) -> 0.1693588 | J46: =IFERROR(-CUMPRINC($F$8/12,$F$9*12,$F$10,(2-1)*12+1,2*12,0),0) -> 775.7782 | K46: =K45+J46 -> 1508.8185 | L46: =IFERROR((H46+J46)/$F$13,0) -> 0.19046841
...

Sheet Dashboard
A2: 🏠 DealWiseRent.com
A4: RENTAL PROPERTY INVESTMENT ANALYSIS TOOL
A6: ⚠ DISCLAIMER: This tool provides rental property investment estimates for informational purposes only. Calculations may contain errors or omissions. Always perform your own due diligence and consult a licensed real estate professional or financial advisor before making any investment decision. DealWiseRent.com assumes no liability for decisions based on this analysis.
A8: 📊 INVESTMENT SUMMARY — Update inputs on the ➜ Calculator sheet
B9: PURCHASE PRICE | E9: TOTAL CASH OUTLAY | H9: MONTHLY MORTGAGE PMT
B10: =Calculator!C7 -> 75000 | E10: =Calculator!F13 -> 36750 | H10: =Calculator!F12 -> 325.76267
B12: ANNUAL CASH FLOW (Outsourced PM) | E12: CASH ROI (Outsourced PM) | H12: NET OPERATING INCOME (Yr 1)
B13: =Calculator!E34 -> 5375.248 | E13: =Calculator!E37 -> 0.14626525 | H13: =Calculator!E32 -> 9284.4
B15: ANNUAL CASH FLOW (Self-Managed) | E15: CASH ROI (Self-Managed) | H15: TOTAL ROI (Year 1)
B16: =Calculator!H34 -> 6560.848 | E16: =Calculator!H37 -> 0.17852648 | H16: =Calculator!E38 -> 0.16621192
A19: 📋 YEAR 1 RESULTS OVERVIEW
B20: METRIC | E20: OUTSOURCED PM | H20: SELF-MANAGED
B21: Gross Annual Rent | E21: =Calculator!E19 -> 15600 | H21: =Calculator!H19 -> 15600
B22: Vacancy / Credit Loss | E22: =Calculator!E20 -> -780 | H22: =Calculator!H20 -> -780
B23: Effective Gross Income | E23: =Calculator!E21 -> 14820 | H23: =Calculator!H21 -> 14820
B24: Total Operating Expenses | E24: =Calculator!E30 -> -5535.6 | H24: =Calculator!H30 -> -4350
B25: Net Operating Income (NOI) | E25: =Calculator!E32 -> 9284.4 | H25: =Calculator!H32 -> 10470
B26: Annual Mortgage | E26: =Calculator!E33 -> -3909.152 | H26: =Calculator!H33 -> -3909.152
B27: Annual Cash Flow | E27: =Calculator!E34 -> 5375.248 | H27: =Calculator!H34 -> 6560.848
B28: Monthly Cash Flow | E28: =Calculator!E35 -> 447.93733 | H28: =Calculator!H35 -> 546.73733
B29: Cash ROI | E29: =Calculator!E37 -> 0.14626525 | H29: =Calculator!H37 -> 0.17852648
B30: Total ROI (CF + Equity, Yr1) | E30: =Calculator!E38 -> 0.16621192 | H30: =Calculator!H38 -> 0.19847315
B31: Cap Rate | E31: =Calculator!E39 -> 0.099832258 | H31: =Calculator!H39 -> 0.11258065
B32: Gross Rent Multiplier (GRM) | E32: =Calculator!E40 -> 4.8076923 | H32: =Calculator!H40 -> 4.8076923
A34: © 2025 DealWiseRent.com | Professional Rental Investment Analysis | www.DealWiseRent.com

Sheet Charts
A1: DealWiseRent.com | Investment Performance Charts
A2: 📈 Visual analysis of your 30-year rental property investment performance
A89: ⚠ DISCLAIMER: All charts are estimates for informational purposes only. DealWiseRent.com assumes no liability for investment decisions. © 2025 DealWiseRent.com – www.DealWiseRent.com
A90: © 2025 DealWiseRent.com | www.DealWiseRent.com
